Workbook

Sheet 7
A1: BF Varai Khichdi, Potato Salli, LunchVarai Pulav,Soup,Alu Flower gravy,Potato chips, kakdi singdana salad
A2: Varai Khichdi | B2: Ingredients | C2: Std Qty | D2: Unit | E2: Req Qty | F2: Unit
B3: Varai rice | C3: 3.4166667 | D3: kg | E3: =C3*E$20/C$20 -> 34 | F3: kg
B4: Bhopla | C4: 2.9166667 | D4: kg | E4: =C4*E$20/C$20 -> 29 | F4: kg
B5: Dudhi | C5: 2.9166667 | D5: kg | E5: =C5*E$20/C$20 -> 29 | F5: kg
B6: Alu | C6: 1.25 | D6: kg | E6: =C6*E$20/C$20 -> 13 | F6: kg
B7: Gajar | C7: 1.25 | D7: kg | E7: =C7*E$20/C$20 -> 13 | F7: kg
B8: Groundnut Oil | C8: 1 | D8: ltr | E8: =C8*E$20/C$20 -> 10 | F8: ltr
B9: Jeera | C9: 0.16666667 | D9: ltr | E9: =C9*E$20/C$20 -> 2 | F9: ltr
B10: Hari mirchi split in 2 | C10: 0.16666667 | D10: ltr | E10: =C10*E$20/C$20 -> 2 | F10: ltr
B11: Madrasi Mirchi | C11: 0.16666667 | D11: ltr | E11: =C11*E$20/C$20 -> 2 | F11: ltr
B12: Kadi Patta | C12: 1 | D12: ltr | E12: =C12*E$20/C$20 -> 10 | F12: ltr
B13: Adrak paste | C13: 0.20833333 | D13: ltr | E13: =C13*E$20/C$20 -> 2 | F13: ltr
B14: Kashmiri Michi Pwd | C14: 0.20833333 | D14: cup | E14: =C14*E$20/C$20 -> 2 | F14: cup
... B19: YIELD | C19: 1 | D19: tub | E19: =C19*E$20/C$20 -> 10 | F19: tub
B20: YIELD | C20: 35 | D20: ltr | E20: =35*10 -> 350 | F20: ltr
A23: Potato Salli | B23: Salli | C23: 4 | D23: kg | E23: =C23*6.25 -> 25 | F23: kg
B24: Black Pepper Pwd | C24: 0.5 | D24: cup | E24: =C24*6.25 -> 3.125 | F24: cup
B25: Black Salt | C25: 0.5 | D25: cup | E25: =C25*6.25 -> 3.125 | F25: cup
B26: Salt | C26: 0.5 | D26: cup | E26: =C26*6.25 -> 3.125 | F26: cup
B27: Oil for frying | E27: =C27*6.25 -> 0
B28: Expected Yield | C28: 1 | D28: tub | E28: =C28*6.25 -> 6.25 | F28: tub
A30: Varai Pulav | B30: Ingredients | C30: Std Qty | D30: Unit | E30: Req Qty | F30: Unit | G30: Req Qty | H30: Unit
B31: Varai rice | C31: 30 | D31: kg | E31: =C31/1.2 -> 25 | F31: kg | G31: =E31*2 -> 50 | H31: kg
B32: Groundnut oil for tadka | C32: 10 | D32: ltr | E32: =C32/1.2 -> 8.3 | F32: ltr | G32: =E32*2 -> 16.6 | H32: ltr
B33: Tejpatta | C33: 1 | D33: ltr | E33: =C33/1.2 -> 0.8 | F33: ltr | G33: =E33*2 -> 1.6 | H33: ltr
B34: Jeera | C34: 0.75 | D34: ltr | E34: =C34/1.2 -> 0.6 | F34: ltr | G34: =E34*2 -> 1.2 | H34: ltr
B35: kadi patta | C35: 2 | D35: ltr | E35: =C35/1.2 -> 1.7 | F35: ltr | G35: =E35*2 -> 3.4 | H35: ltr
B36: Gajar | C36: 5 | D36: ltr | E36: =C36/1.2 -> 4.2 | F36: ltr | G36: =E36*2 -> 8.4 | H36: ltr
C37: 4 | D37: kg | E37: =C37/1.2 -> 3.3 | F37: kg | G37: =E37*2 -> 6.6 | H37: kg
B38: Cabbage | C38: 30 | D38: ltr | E38: =C38/1.2 -> 25 | F38: ltr | G38: =E38*2 -> 50 | H38: ltr
C39: 12 | D39: kg | E39: =C39/1.2 -> 10 | F39: kg | G39: =E39*2 -> 20 | H39: kg
B40: Capsicum | C40: 5 | D40: ltr | E40: =C40/1.2 -> 4.2 | F40: ltr | G40: =E40*2 -> 8.4 | H40: ltr
C41: 3.5 | D41: kg | E41: =C41/1.2 -> 2.9 | F41: kg | G41: =E41*2 -> 5.8 | H41: kg
B42: Salt | C42: 4 | D42: cup | E42: =C42/1.2 -> 3.3 | F42: cup | G42: =E42*2 -> 6.6 | H42: cup
B43: Everest Pulav Masala | C43: 2 | D43: cup | E43: =C43/1.2 -> 1.7 | F43: cup | G43: =E43*2 -> 3.4 | H43: cup
A44: 2 x Vol of Varai | B44: Hot water | C44: 60 | D44: ltr | E44: =C44/1.2 -> 50 | F44: ltr | G44: =E44*2 -> 100 | H44: ltr
B45: sugar | C45: 4 | D45: cup | E45: =C45/1.2 -> 3.3 | F45: cup | G45: =E45*2 -> 6.6 | H45: cup
A46: DGP | B46: Yield | C46: 3.5 | D46: Tub | E46: =C46/1.2 -> 2.9 | F46: Tub | G46: =E46*2 -> 5.8 | H46: Tub
A49: Ekadasi soup | B49: Ingredients | C49: Std Qty | D49: Unit | E49: Req Qty | F49: Unit | G49: Req Qty | H49: Unit
...

Sheet recipe_ingred_list
A1: Recipe Name | B1: S.No | D1: Ingredient | E1: S.No | F1: ltr | G1: Liter | H1: 1
A2: Varai Khichdi | B2: 1 | C2: varai-khichdi | D2: adrak | E2: 1 | F2: kg | G2: Kilo Gram | H2: 2 | J2: 2 | K2: kg | L2: Kilo Gram | M2: 2
A3: EKADASI KHICHDI NON-SPICY | B3: 2 | C3: ekadasi-khichdi-non-spicy | D3: ajinomoto | E3: 2 | F3: pcs | G3: Pieces | H3: 3 | J3: 3 | K3: gm | L3: gm | M3: 7
A4: ALU CHURCHURY | B4: 3 | C4: alu-churchury | D4: akha dhaniya | E4: 3 | F4: tub | G4: Tub 35 Lt | H4: 4 | J4: 4 | K4: 0 | L4: 0 | M4: 2
A5: Alu Jeera | B5: 4 | C5: alu-jeera | D5: akha methi | E5: 4 | F5: cup | G5: cup 200 ml | H5: 5 | J5: 5
A6: Alu Kala Chana Chat | B6: 5 | C6: alu-kala-chana-chat | D6: akha moong | E6: 5 | F6: bkt | G6: bkt | H6: 6 | J6: 6
A7: ALU PARATHA | B7: 6 | C7: alu-paratha | D7: akkha madrasi mirchi | E7: 6 | F7: gm | G7: gm | H7: 7 | J7: 7
A8: Barley / Ragi / Regira Malt | B8: 7 | C8: barley-ragi-regira-malt | D8: almonds | E8: 7 | F8: bndl | G8: bndl | H8: 8
A9: Beans Tahini Sauce | B9: 8 | C9: beans-tahini-sauce | D9: alu | E9: 8 | F9: mutthi | G9: mutthi | H9: 9
A10: Bhopla KM | B10: 9 | C10: bhopla-km | D10: ambahaldi | E10: 9 | F10: tsp | G10: tsp | H10: 10
A11: Biryani Dum Layer | B11: 10 | C11: biryani-dum-layer | D11: amchur | E11: 10 | F11: pkt | G11: pkt | H11: 11
A12: Boondi raita | B12: 11 | C12: boondi-raita | D12: amla churna | E12: 11 | F12: ml | G12: ml | H12: 12
A13: Brokoli Sautee | B13: 12 | C13: brokoli-sautee | D13: amul butter | E13: 12 | F13: tin | G13: tin | H13: 13
A14: Chole Krsna Balaram | B14: 13 | C14: chole-krsna-balaram | D14: amul fresh cream | E14: 13
A15: Coconut Chutney | B15: 14 | C15: coconut-chutney | D15: annapoorna sambar masala | E15: 14
A16: Dahi Rice | B16: 15 | C16: dahi-rice | D16: apple green colour | E16: 15 | J16: 16 | K16: tub | L16: Tub 35 Lt | M16: 4
A17: Dahi Baingan | B17: 16 | C17: dahi-baingan | D17: baby corn | E17: 16 | J17: 17 | K17: cup | L17: cup 200 ml | M17: 5
A18: Dahi Bhindi | B18: 17 | C18: dahi-bhindi | D18: badi sauf | E18: 17 | J18: 18 | K18: bkt | L18: bkt | M18: 6
A19: Dahi Patol | B19: 18 | C19: dahi-patol | D19: badsah pulav masala | E19: 18 | J19: 19 | K19: mutthi | L19: mutthi | M19: 9
A20: DHOKLA | B20: 19 | C20: dhokla | D20: badshah pav bhaji masala | E20: 19 | J20: 20 | K20: tsp | L20: tsp | M20: 10
A21: Dosa Bhaji Dry | B21: 20 | C21: dosa-bhaji-dry | D21: badshah rajwadi garam masala | E21: 20 | J21: 21 | K21: ml | L21: ml | M21: 12
A22: Dwadashi / Spicy Khichadi | B22: 21 | C22: dwadashi-spicy-khichadi | D22: baingan | E22: 21 | J22: 22 | K22: tin | L22: tin | M22: 13
A23: EKADASHI CHUTNEY | B23: 22 | C23: ekadashi-chutney | D23: banana | E23: 22 | J23: 23 | K23: ltr | L23: Liter | M23: 1
A24: EKADASHI KHICHDI SPICY | B24: 23 | C24: ekadashi-khichdi-spicy | D24: barley | E24: 23 | J24: 24 | K24: 0 | L24: 0 | M24: 1
A25: EKADASHI UPMA | B25: 24 | C25: ekadashi-upma | D25: basil leaves | E25: 24 | J25: 25
A26: FENNEL TEA | B26: 25 | C26: fennel-tea | D26: basmati rice | E26: 25
A27: Gauranga fried Rice | B27: 26 | C27: gauranga-fried-rice | D27: batter yield | E27: 26
A28: GINGER LEMON TEA | B28: 27 | C28: ginger-lemon-tea | D28: beans | E28: 27
A29: green chutney -Dhokla AND MUMBAI BHEL | B29: 28 | C29: green-chutney-dhokla-and-mumbai-bhel | D29: besan | E29: 28 | J29: 29 | K29: pkt | L29: pkt | M29: 11
A30: Green curry | B30: 29 | C30: green-curry | D30: bhindi | E30: 29 | J30: 30 | K30: bndl | L30: bndl | M30: 8
A31: Herbal Tea | B31: 30 | C31: herbal-tea | D31: bhopla | E31: 30 | J31: 31 | K31: pcs | L31: Pieces | M31: 3
A32: Idli | B32: 31 | C32: idli | D32: black pepper | E32: 31 | J32: 32 | K32: 0 | L32: 0 | M32: 3
A33: Italian Salad | B33: 32 | C33: italian-salad | D33: black salt | E33: 32 | J33: 33
A34: Jackfruit gravy | B34: 33 | C34: jackfruit-gravy | D34: black til | E34: 33 | J34: 34
A35: Jeera Rice | B35: 34 | C35: jeera-rice | D35: boondi | E35: 34
A36: JP Khichadi | B36: 35 | C36: jp-khichadi | D36: bread improver | E36: 35
A37: Kerela Round | B37: 36 | C37: kerela-round | D37: broccoli | E37: 36
A38: Khichadi | B38: 37 | C38: khichadi | D38: brown sugar | E38: 37
A39: KOKAM | B39: 38 | C39: kokam | D39: butter | E39: 38
A40: Kothimbit wadi | B40: 39 | C40: kothimbit-wadi | D40: cabbage | E40: 39
...

Sheet recipedetails
G1: 1 | L1: mass_unit | N1: volume_unit | P1: pieces_unit | AB1: ="'"&AA7&"'" -> '3.42'
G2: 2 | L2: kg | N2: ltr | P2: pcs | AF2: a = Client().post('/recipes/varai-khichdi/detail/', {'recipe' : '1', 'ingredient' : '201', 'name' : 'Varai rice', 'mass_unit' : '2', 'mass_quantity' : '3.42', 'volume_unit' : '', 'volume_quantity' : '0', 'pieces_unit' : '', 'pieces_quantity' : '0', 'cooking_notes' : ''}).status_code; print('%s :: %s :: %s :: %s :: %s' %(a,7,'Varai rice','varai','Varai Khichdi'))
G3: 3 | N3: tub35
G4: 4 | N4: cup200
G5: 5 | AM5: from django.test import Client
G6: 6 | H6: Checking | I6: recipe | J6: Name | K6: mass_quantity | L6: mass_unit | M6: volume_quantity | N6: volume_unit | O6: pieces_quantity | P6: pieces_unit | Q6: Cooking instructions | R6: =VLOOKUP(J6,ingredient!$N$4:$O$553,2,0) -> #N/A | U6: recipe | X6: Name | Y6: Ingredient | AA6: mass_quantity | AB6: mass_unit | AC6: code | AD6: volume_quantity | AE6: volume_unit | AF6: code | AG6: pieces_quantity | AH6: pieces_unit | AI6: code | AJ6: Cooking instructions | AK6: 6 | AM6: from django.test import Client
G7: 7 | H7: Varai rice | I7: Varai Khichdi | J7: Varai rice | K7: 3.42 | L7: kg | R7: =VLOOKUP(J7,ingredient!$N$4:$O$553,2,0) -> varai | U7: =I7 -> Varai Khichdi | V7: =VLOOKUP(U7,recipe_ingred_list!$A$2:$B$300,2,0) -> 1 | W7: ="/recipes/"&VLOOKUP(U7,recipe_ingred_list!$A$2:$C$300,3,0)&"/detail/" -> /recipes/varai-khichdi/detail/ | X7: =J7 -> Varai rice | Y7: =R7 -> varai | Z7: =VLOOKUP(Y7,recipe_ingred_list!$D$2:$E$500,2,0) -> 201 | AA7: =K7 -> 3.42 | AB7: =L7 -> kg | AC7: =VLOOKUP(AB7,recipe_ingred_list!$K$2:$M$7,3,0) -> 2 | AD7: =M7 -> 0 | AE7: =N7 -> 0 | AF7: =VLOOKUP(AE7,recipe_ingred_list!$K$16:$M$25,3,0) -> 1 | AG7: =O7 -> 0 | AH7: =P7 -> 0 | AI7: =VLOOKUP(AH7,recipe_ingred_list!$K$29:$M$34,3,0) -> 3 | AJ7: =IF(Q7="","",Q7) | AK7: =AK6+1 -> 7 | AL7: =Y7 -> varai | AM7: ="a = Client().post('"&W7&"', {'recipe' : '"&V7&"', 'ingredient' : '"&Z7&"', 'name' : '"&X7&"', 'mass_unit' : '"&AC7&"', 'mass_quantity' : '"&ROUND(AA7,3)&"', 'volume_unit' : '"&AF7&"', 'volume_quantity' : '"&ROUND(AD7,3)&"', 'pieces_unit' : '"&AI7&"', 'pieces_quantity' : '"&ROUND(AG7,3)&"', 'cooking_notes' : '"&AJ7&"'}).status_code; print('%s :: %s :: %s :: %s :: %s' %(a,"&G7&",'"&X7&"','"&Y7&"','"&U7&"'))" -> a = Client().post('/recipes/varai-khichdi/detail/', {'recipe' : '1', 'ingredient' : '201', 'name' : 'Varai rice', 'mass_unit' : '2', 'mass_quantity' : '3.42', 'volume_unit' : '1', 'volume_quantity' : '0', 'pieces_unit' : '3', 'pieces_quantity' : '0', 'cooking_notes' : ''}).status_code; print('%s :: %s :: %s :: %s :: %s' %(a,7,'Varai rice','varai','Varai Khichdi'))
G8: 8 | H8: Bhopla | I8: Varai Khichdi | J8: Bhopla | K8: 2.9166667 | L8: kg | R8: =VLOOKUP(J8,ingredient!$N$4:$O$553,2,0) -> bhopla | U8: =I8 -> Varai Khichdi | V8: =VLOOKUP(U8,recipe_ingred_list!$A$2:$B$300,2,0) -> 1 | W8: ="/recipes/"&VLOOKUP(U8,recipe_ingred_list!$A$2:$C$300,3,0)&"/detail/" -> /recipes/varai-khichdi/detail/ | X8: =J8 -> Bhopla | Y8: =R8 -> bhopla | Z8: =VLOOKUP(Y8,recipe_ingred_list!$D$2:$E$500,2,0) -> 30 | AA8: =K8 -> 2.9166667 | AB8: =L8 -> kg | AC8: =VLOOKUP(AB8,recipe_ingred_list!$K$2:$M$7,3,0) -> 2 | AD8: =M8 -> 0 | AE8: =N8 -> 0 | AF8: =VLOOKUP(AE8,recipe_ingred_list!$K$16:$M$25,3,0) -> 1 | AG8: =O8 -> 0 | AH8: =P8 -> 0 | AI8: =VLOOKUP(AH8,recipe_ingred_list!$K$29:$M$34,3,0) -> 3 | AJ8: =IF(Q8="","",Q8) | AK8: =AK7+1 -> 8 | AL8: =Y8 -> bhopla | AM8: ="a = Client().post('"&W8&"', {'recipe' : '"&V8&"', 'ingredient' : '"&Z8&"', 'name' : '"&X8&"', 'mass_unit' : '"&AC8&"', 'mass_quantity' : '"&ROUND(AA8,3)&"', 'volume_unit' : '"&AF8&"', 'volume_quantity' : '"&ROUND(AD8,3)&"', 'pieces_unit' : '"&AI8&"', 'pieces_quantity' : '"&ROUND(AG8,3)&"', 'cooking_notes' : '"&AJ8&"'}).status_code; print('%s :: %s :: %s :: %s :: %s' %(a,"&G8&",'"&X8&"','"&Y8&"','"&U8&"'))" -> a = Client().post('/recipes/varai-khichdi/detail/', {'recipe' : '1', 'ingredient' : '30', 'name' : 'Bhopla', 'mass_unit' : '2', 'mass_quantity' : '2.917', 'volume_unit' : '1', 'volume_quantity' : '0', 'pieces_unit' : '3', 'pieces_quantity' : '0', 'cooking_notes' : ''}).status_code; print('%s :: %s :: %s :: %s :: %s' %(a,8,'Bhopla','bhopla','Varai Khichdi'))
G9: 9 | H9: Dudhi | I9: Varai Khichdi | J9: Dudhi | K9: 2.9166667 | L9: kg | R9: =VLOOKUP(J9,ingredient!$N$4:$O$553,2,0) -> dudhi | U9: =I9 -> Varai Khichdi | V9: =VLOOKUP(U9,recipe_ingred_list!$A$2:$B$300,2,0) -> 1 | W9: ="/recipes/"&VLOOKUP(U9,recipe_ingred_list!$A$2:$C$300,3,0)&"/detail/" -> /recipes/varai-khichdi/detail/ | X9: =J9 -> Dudhi | Y9: =R9 -> dudhi | Z9: =VLOOKUP(Y9,recipe_ingred_list!$D$2:$E$500,2,0) -> 69 | AA9: =K9 -> 2.9166667 | AB9: =L9 -> kg | AC9: =VLOOKUP(AB9,recipe_ingred_list!$K$2:$M$7,3,0) -> 2 | AD9: =M9 -> 0 | AE9: =N9 -> 0 | AF9: =VLOOKUP(AE9,recipe_ingred_list!$K$16:$M$25,3,0) -> 1 | AG9: =O9 -> 0 | AH9: =P9 -> 0 | AI9: =VLOOKUP(AH9,recipe_ingred_list!$K$29:$M$34,3,0) -> 3 | AJ9: =IF(Q9="","",Q9) | AK9: =AK8+1 -> 9 | AL9: =Y9 -> dudhi | AM9: ="a = Client().post('"&W9&"', {'recipe' : '"&V9&"', 'ingredient' : '"&Z9&"', 'name' : '"&X9&"', 'mass_unit' : '"&AC9&"', 'mass_quantity' : '"&ROUND(AA9,3)&"', 'volume_unit' : '"&AF9&"', 'volume_quantity' : '"&ROUND(AD9,3)&"', 'pieces_unit' : '"&AI9&"', 'pieces_quantity' : '"&ROUND(AG9,3)&"', 'cooking_notes' : '"&AJ9&"'}).status_code; print('%s :: %s :: %s :: %s :: %s' %(a,"&G9&",'"&X9&"','"&Y9&"','"&U9&"'))" -> a = Client().post('/recipes/varai-khichdi/detail/', {'recipe' : '1', 'ingredient' : '69', 'name' : 'Dudhi', 'mass_unit' : '2', 'mass_quantity' : '2.917', 'volume_unit' : '1', 'volume_quantity' : '0', 'pieces_unit' : '3', 'pieces_quantity' : '0', 'cooking_notes' : ''}).status_code; print('%s :: %s :: %s :: %s :: %s' %(a,9,'Dudhi','dudhi','Varai Khichdi'))
G10: 10 | H10: Alu | I10: Varai Khichdi | J10: Alu | K10: 1.25 | L10: kg | R10: =VLOOKUP(J10,ingredient!$N$4:$O$553,2,0) -> alu | U10: =I10 -> Varai Khichdi | V10: =VLOOKUP(U10,recipe_ingred_list!$A$2:$B$300,2,0) -> 1 | W10: ="/recipes/"&VLOOKUP(U10,recipe_ingred_list!$A$2:$C$300,3,0)&"/detail/" -> /recipes/varai-khichdi/detail/ | X10: =J10 -> Alu | Y10: =R10 -> alu | Z10: =VLOOKUP(Y10,recipe_ingred_list!$D$2:$E$500,2,0) -> 8 | AA10: =K10 -> 1.25 | AB10: =L10 -> kg | AC10: =VLOOKUP(AB10,recipe_ingred_list!$K$2:$M$7,3,0) -> 2 | AD10: =M10 -> 0 | AE10: =N10 -> 0 | AF10: =VLOOKUP(AE10,recipe_ingred_list!$K$16:$M$25,3,0) -> 1 | AG10: =O10 -> 0 | AH10: =P10 -> 0 | AI10: =VLOOKUP(AH10,recipe_ingred_list!$K$29:$M$34,3,0) -> 3 | AJ10: =IF(Q10="","",Q10) | AK10: =AK9+1 -> 10 | AL10: =Y10 -> alu | AM10: ="a = Client().post('"&W10&"', {'recipe' : '"&V10&"', 'ingredient' : '"&Z10&"', 'name' : '"&X10&"', 'mass_unit' : '"&AC10&"', 'mass_quantity' : '"&ROUND(AA10,3)&"', 'volume_unit' : '"&AF10&"', 'volume_quantity' : '"&ROUND(AD10,3)&"', 'pieces_unit' : '"&AI10&"', 'pieces_quantity' : '"&ROUND(AG10,3)&"', 'cooking_notes' : '"&AJ10&"'}).status_code; print('%s :: %s :: %s :: %s :: %s' %(a,"&G10&",'"&X10&"','"&Y10&"','"&U10&"'))" -> a = Client().post('/recipes/varai-khichdi/detail/', {'recipe' : '1', 'ingredient' : '8', 'name' : 'Alu', 'mass_unit' : '2', 'mass_quantity' : '1.25', 'volume_unit' : '1', 'volume_quantity' : '0', 'pieces_unit' : '3', 'pieces_quantity' : '0', 'cooking_notes' : ''}).status_code; print('%s :: %s :: %s :: %s :: %s' %(a,10,'Alu','alu','Varai Khichdi'))
G11: 11 | H11: Gajar | I11: Varai Khichdi | J11: Gajar | K11: 1.25 | L11: kg | R11: =VLOOKUP(J11,ingredient!$N$4:$O$553,2,0) -> gajar | U11: =I11 -> Varai Khichdi | V11: =VLOOKUP(U11,recipe_ingred_list!$A$2:$B$300,2,0) -> 1 | W11: ="/recipes/"&VLOOKUP(U11,recipe_ingred_list!$A$2:$C$300,3,0)&"/detail/" -> /recipes/varai-khichdi/detail/ | X11: =J11 -> Gajar | Y11: =R11 -> gajar | Z11: =VLOOKUP(Y11,recipe_ingred_list!$D$2:$E$500,2,0) -> 79 | AA11: =K11 -> 1.25 | AB11: =L11 -> kg | AC11: =VLOOKUP(AB11,recipe_ingred_list!$K$2:$M$7,3,0) -> 2 | AD11: =M11 -> 0 | AE11: =N11 -> 0 | AF11: =VLOOKUP(AE11,recipe_ingred_list!$K$16:$M$25,3,0) -> 1 | AG11: =O11 -> 0 | AH11: =P11 -> 0 | AI11: =VLOOKUP(AH11,recipe_ingred_list!$K$29:$M$34,3,0) -> 3 | AJ11: =IF(Q11="","",Q11) | AK11: =AK10+1 -> 11 | AL11: =Y11 -> gajar | AM11: ="a = Client().post('"&W11&"', {'recipe' : '"&V11&"', 'ingredient' : '"&Z11&"', 'name' : '"&X11&"', 'mass_unit' : '"&AC11&"', 'mass_quantity' : '"&ROUND(AA11,3)&"', 'volume_unit' : '"&AF11&"', 'volume_quantity' : '"&ROUND(AD11,3)&"', 'pieces_unit' : '"&AI11&"', 'pieces_quantity' : '"&ROUND(AG11,3)&"', 'cooking_notes' : '"&AJ11&"'}).status_code; print('%s :: %s :: %s :: %s :: %s' %(a,"&G11&",'"&X11&"','"&Y11&"','"&U11&"'))" -> a = Client().post('/recipes/varai-khichdi/detail/', {'recipe' : '1', 'ingredient' : '79', 'name' : 'Gajar', 'mass_unit' : '2', 'mass_quantity' : '1.25', 'volume_unit' : '1', 'volume_quantity' : '0', 'pieces_unit' : '3', 'pieces_quantity' : '0', 'cooking_notes' : ''}).status_code; print('%s :: %s :: %s :: %s :: %s' %(a,11,'Gajar','gajar','Varai Khichdi'))
G12: 12 | H12: Ground nut Oil | I12: Varai Khichdi | J12: Groundnut Oil | M12: 1 | N12: ltr | R12: =VLOOKUP(J12,ingredient!$N$4:$O$553,2,0) -> ground nut oil | U12: =I12 -> Varai Khichdi | V12: =VLOOKUP(U12,recipe_ingred_list!$A$2:$B$300,2,0) -> 1 | W12: ="/recipes/"&VLOOKUP(U12,recipe_ingred_list!$A$2:$C$300,3,0)&"/detail/" -> /recipes/varai-khichdi/detail/ | X12: =J12 -> Groundnut Oil | Y12: =R12 -> ground nut oil | Z12: =VLOOKUP(Y12,recipe_ingred_list!$D$2:$E$500,2,0) -> 89 | AA12: =K12 -> 0 | AB12: =L12 -> 0 | AC12: =VLOOKUP(AB12,recipe_ingred_list!$K$2:$M$7,3,0) -> 2 | AD12: =M12 -> 1 | AE12: =N12 -> ltr | AF12: =VLOOKUP(AE12,recipe_ingred_list!$K$16:$M$25,3,0) -> 1 | AG12: =O12 -> 0 | AH12: =P12 -> 0 | AI12: =VLOOKUP(AH12,recipe_ingred_list!$K$29:$M$34,3,0) -> 3 | AJ12: =IF(Q12="","",Q12) | AK12: =AK11+1 -> 12 | AL12: =Y12 -> ground nut oil | AM12: ="a = Client().post('"&W12&"', {'recipe' : '"&V12&"', 'ingredient' : '"&Z12&"', 'name' : '"&X12&"', 'mass_unit' : '"&AC12&"', 'mass_quantity' : '"&ROUND(AA12,3)&"', 'volume_unit' : '"&AF12&"', 'volume_quantity' : '"&ROUND(AD12,3)&"', 'pieces_unit' : '"&AI12&"', 'pieces_quantity' : '"&ROUND(AG12,3)&"', 'cooking_notes' : '"&AJ12&"'}).status_code; print('%s :: %s :: %s :: %s :: %s' %(a,"&G12&",'"&X12&"','"&Y12&"','"&U12&"'))" -> a = Client().post('/recipes/varai-khichdi/detail/', {'recipe' : '1', 'ingredient' : '89', 'name' : 'Groundnut Oil', 'mass_unit' : '2', 'mass_quantity' : '0', 'volume_unit' : '1', 'volume_quantity' : '1', 'pieces_unit' : '3', 'pieces_quantity' : '0', 'cooking_notes' : ''}).status_code; print('%s :: %s :: %s :: %s :: %s' %(a,12,'Groundnut Oil','ground nut oil','Varai Khichdi'))
G13: 13 | H13: Jeera | I13: Varai Khichdi | J13: Jeera | M13: 0.16666667 | N13: ltr | R13: =VLOOKUP(J13,ingredient!$N$4:$O$553,2,0) -> jeera | U13: =I13 -> Varai Khichdi | V13: =VLOOKUP(U13,recipe_ingred_list!$A$2:$B$300,2,0) -> 1 | W13: ="/recipes/"&VLOOKUP(U13,recipe_ingred_list!$A$2:$C$300,3,0)&"/detail/" -> /recipes/varai-khichdi/detail/ | X13: =J13 -> Jeera | Y13: =R13 -> jeera | Z13: =VLOOKUP(Y13,recipe_ingred_list!$D$2:$E$500,2,0) -> 102 | AA13: =K13 -> 0 | AB13: =L13 -> 0 | AC13: =VLOOKUP(AB13,recipe_ingred_list!$K$2:$M$7,3,0) -> 2 | AD13: =M13 -> 0.16666667 | AE13: =N13 -> ltr | AF13: =VLOOKUP(AE13,recipe_ingred_list!$K$16:$M$25,3,0) -> 1 | AG13: =O13 -> 0 | AH13: =P13 -> 0 | AI13: =VLOOKUP(AH13,recipe_ingred_list!$K$29:$M$34,3,0) -> 3 | AJ13: =IF(Q13="","",Q13) | AK13: =AK12+1 -> 13 | AL13: =Y13 -> jeera | AM13: ="a = Client().post('"&W13&"', {'recipe' : '"&V13&"', 'ingredient' : '"&Z13&"', 'name' : '"&X13&"', 'mass_unit' : '"&AC13&"', 'mass_quantity' : '"&ROUND(AA13,3)&"', 'volume_unit' : '"&AF13&"', 'volume_quantity' : '"&ROUND(AD13,3)&"', 'pieces_unit' : '"&AI13&"', 'pieces_quantity' : '"&ROUND(AG13,3)&"', 'cooking_notes' : '"&AJ13&"'}).status_code; print('%s :: %s :: %s :: %s :: %s' %(a,"&G13&",'"&X13&"','"&Y13&"','"&U13&"'))" -> a = Client().post('/recipes/varai-khichdi/detail/', {'recipe' : '1', 'ingredient' : '102', 'name' : 'Jeera', 'mass_unit' : '2', 'mass_quantity' : '0', 'volume_unit' : '1', 'volume_quantity' : '0.167', 'pieces_unit' : '3', 'pieces_quantity' : '0', 'cooking_notes' : ''}).status_code; print('%s :: %s :: %s :: %s :: %s' %(a,13,'Jeera','jeera','Varai Khichdi'))
G14: 14 | H14: Hari mirchi | I14: Varai Khichdi | J14: Hari mirchi split in 2 | M14: 0.16666667 | N14: ltr | R14: =VLOOKUP(J14,ingredient!$N$4:$O$553,2,0) -> hari mirchi | U14: =I14 -> Varai Khichdi | V14: =VLOOKUP(U14,recipe_ingred_list!$A$2:$B$300,2,0) -> 1 | W14: ="/recipes/"&VLOOKUP(U14,recipe_ingred_list!$A$2:$C$300,3,0)&"/detail/" -> /recipes/varai-khichdi/detail/ | X14: =J14 -> Hari mirchi split in 2 | Y14: =R14 -> hari mirchi | Z14: =VLOOKUP(Y14,recipe_ingred_list!$D$2:$E$500,2,0) -> 93 | AA14: =K14 -> 0 | AB14: =L14 -> 0 | AC14: =VLOOKUP(AB14,recipe_ingred_list!$K$2:$M$7,3,0) -> 2 | AD14: =M14 -> 0.16666667 | AE14: =N14 -> ltr | AF14: =VLOOKUP(AE14,recipe_ingred_list!$K$16:$M$25,3,0) -> 1 | AG14: =O14 -> 0 | AH14: =P14 -> 0 | AI14: =VLOOKUP(AH14,recipe_ingred_list!$K$29:$M$34,3,0) -> 3 | AJ14: =IF(Q14="","",Q14) | AK14: =AK13+1 -> 14 | AL14: =Y14 -> hari mirchi | AM14: ="a = Client().post('"&W14&"', {'recipe' : '"&V14&"', 'ingredient' : '"&Z14&"', 'name' : '"&X14&"', 'mass_unit' : '"&AC14&"', 'mass_quantity' : '"&ROUND(AA14,3)&"', 'volume_unit' : '"&AF14&"', 'volume_quantity' : '"&ROUND(AD14,3)&"', 'pieces_unit' : '"&AI14&"', 'pieces_quantity' : '"&ROUND(AG14,3)&"', 'cooking_notes' : '"&AJ14&"'}).status_code; print('%s :: %s :: %s :: %s :: %s' %(a,"&G14&",'"&X14&"','"&Y14&"','"&U14&"'))" -> a = Client().post('/recipes/varai-khichdi/detail/', {'recipe' : '1', 'ingredient' : '93', 'name' : 'Hari mirchi split in 2', 'mass_unit' : '2', 'mass_quantity' : '0', 'volume_unit' : '1', 'volume_quantity' : '0.167', 'pieces_unit' : '3', 'pieces_quantity' : '0', 'cooking_notes' : ''}).status_code; print('%s :: %s :: %s :: %s :: %s' %(a,14,'Hari mirchi split in 2','hari mirchi','Varai Khichdi'))
G15: 15 | H15: Madrasi Mirchi | I15: Varai Khichdi | J15: Madrasi Mirchi | M15: 0.16666667 | N15: ltr | R15: =VLOOKUP(J15,ingredient!$N$4:$O$553,2,0) -> madrasi mirchi powder | U15: =I15 -> Varai Khichdi | V15: =VLOOKUP(U15,recipe_ingred_list!$A$2:$B$300,2,0) -> 1 | W15: ="/recipes/"&VLOOKUP(U15,recipe_ingred_list!$A$2:$C$300,3,0)&"/detail/" -> /recipes/varai-khichdi/detail/ | X15: =J15 -> Madrasi Mirchi | Y15: =R15 -> madrasi mirchi powder | Z15: =VLOOKUP(Y15,recipe_ingred_list!$D$2:$E$500,2,0) -> 135 | AA15: =K15 -> 0 | AB15: =L15 -> 0 | AC15: =VLOOKUP(AB15,recipe_ingred_list!$K$2:$M$7,3,0) -> 2 | AD15: =M15 -> 0.16666667 | AE15: =N15 -> ltr | AF15: =VLOOKUP(AE15,recipe_ingred_list!$K$16:$M$25,3,0) -> 1 | AG15: =O15 -> 0 | AH15: =P15 -> 0 | AI15: =VLOOKUP(AH15,recipe_ingred_list!$K$29:$M$34,3,0) -> 3 | AJ15: =IF(Q15="","",Q15) | AK15: =AK14+1 -> 15 | AL15: =Y15 -> madrasi mirchi powder | AM15: ="a = Client().post('"&W15&"', {'recipe' : '"&V15&"', 'ingredient' : '"&Z15&"', 'name' : '"&X15&"', 'mass_unit' : '"&AC15&"', 'mass_quantity' : '"&ROUND(AA15,3)&"', 'volume_unit' : '"&AF15&"', 'volume_quantity' : '"&ROUND(AD15,3)&"', 'pieces_unit' : '"&AI15&"', 'pieces_quantity' : '"&ROUND(AG15,3)&"', 'cooking_notes' : '"&AJ15&"'}).status_code; print('%s :: %s :: %s :: %s :: %s' %(a,"&G15&",'"&X15&"','"&Y15&"','"&U15&"'))" -> a = Client().post('/recipes/varai-khichdi/detail/', {'recipe' : '1', 'ingredient' : '135', 'name' : 'Madrasi Mirchi', 'mass_unit' : '2', 'mass_quantity' : '0', 'volume_unit' : '1', 'volume_quantity' : '0.167', 'pieces_unit' : '3', 'pieces_quantity' : '0', 'cooking_notes' : ''}).status_code; print('%s :: %s :: %s :: %s :: %s' %(a,15,'Madrasi Mirchi','madrasi mirchi powder','Varai Khichdi'))
G16: 16 | H16: Kadi Patta | I16: Varai Khichdi | J16: Kadi Patta | M16: 1 | N16: ltr | R16: =VLOOKUP(J16,ingredient!$N$4:$O$553,2,0) -> kadi patta | U16: =I16 -> Varai Khichdi | V16: =VLOOKUP(U16,recipe_ingred_list!$A$2:$B$300,2,0) -> 1 | W16: ="/recipes/"&VLOOKUP(U16,recipe_ingred_list!$A$2:$C$300,3,0)&"/detail/" -> /recipes/varai-khichdi/detail/ | X16: =J16 -> Kadi Patta | Y16: =R16 -> kadi patta | Z16: =VLOOKUP(Y16,recipe_ingred_list!$D$2:$E$500,2,0) -> 105 | AA16: =K16 -> 0 | AB16: =L16 -> 0 | AC16: =VLOOKUP(AB16,recipe_ingred_list!$K$2:$M$7,3,0) -> 2 | AD16: =M16 -> 1 | AE16: =N16 -> ltr | AF16: =VLOOKUP(AE16,recipe_ingred_list!$K$16:$M$25,3,0) -> 1 | AG16: =O16 -> 0 | AH16: =P16 -> 0 | AI16: =VLOOKUP(AH16,recipe_ingred_list!$K$29:$M$34,3,0) -> 3 | AJ16: =IF(Q16="","",Q16) | AK16: =AK15+1 -> 16 | AL16: =Y16 -> kadi patta | AM16: ="a = Client().post('"&W16&"', {'recipe' : '"&V16&"', 'ingredient' : '"&Z16&"', 'name' : '"&X16&"', 'mass_unit' : '"&AC16&"', 'mass_quantity' : '"&ROUND(AA16,3)&"', 'volume_unit' : '"&AF16&"', 'volume_quantity' : '"&ROUND(AD16,3)&"', 'pieces_unit' : '"&AI16&"', 'pieces_quantity' : '"&ROUND(AG16,3)&"', 'cooking_notes' : '"&AJ16&"'}).status_code; print('%s :: %s :: %s :: %s :: %s' %(a,"&G16&",'"&X16&"','"&Y16&"','"&U16&"'))" -> a = Client().post('/recipes/varai-khichdi/detail/', {'recipe' : '1', 'ingredient' : '105', 'name' : 'Kadi Patta', 'mass_unit' : '2', 'mass_quantity' : '0', 'volume_unit' : '1', 'volume_quantity' : '1', 'pieces_unit' : '3', 'pieces_quantity' : '0', 'cooking_notes' : ''}).status_code; print('%s :: %s :: %s :: %s :: %s' %(a,16,'Kadi Patta','kadi patta','Varai Khichdi'))
G17: 17 | H17: Adrak | I17: Varai Khichdi | J17: Adrak paste | M17: 0.20833333 | N17: ltr | R17: =VLOOKUP(J17,ingredient!$N$4:$O$553,2,0) -> adrak | U17: =I17 -> Varai Khichdi | V17: =VLOOKUP(U17,recipe_ingred_list!$A$2:$B$300,2,0) -> 1 | W17: ="/recipes/"&VLOOKUP(U17,recipe_ingred_list!$A$2:$C$300,3,0)&"/detail/" -> /recipes/varai-khichdi/detail/ | X17: =J17 -> Adrak paste | Y17: =R17 -> adrak | Z17: =VLOOKUP(Y17,recipe_ingred_list!$D$2:$E$500,2,0) -> 1 | AA17: =K17 -> 0 | AB17: =L17 -> 0 | AC17: =VLOOKUP(AB17,recipe_ingred_list!$K$2:$M$7,3,0) -> 2 | AD17: =M17 -> 0.20833333 | AE17: =N17 -> ltr | AF17: =VLOOKUP(AE17,recipe_ingred_list!$K$16:$M$25,3,0) -> 1 | AG17: =O17 -> 0 | AH17: =P17 -> 0 | AI17: =VLOOKUP(AH17,recipe_ingred_list!$K$29:$M$34,3,0) -> 3 | AJ17: =IF(Q17="","",Q17) | AK17: =AK16+1 -> 17 | AL17: =Y17 -> adrak | AM17: ="a = Client().post('"&W17&"', {'recipe' : '"&V17&"', 'ingredient' : '"&Z17&"', 'name' : '"&X17&"', 'mass_unit' : '"&AC17&"', 'mass_quantity' : '"&ROUND(AA17,3)&"', 'volume_unit' : '"&AF17&"', 'volume_quantity' : '"&ROUND(AD17,3)&"', 'pieces_unit' : '"&AI17&"', 'pieces_quantity' : '"&ROUND(AG17,3)&"', 'cooking_notes' : '"&AJ17&"'}).status_code; print('%s :: %s :: %s :: %s :: %s' %(a,"&G17&",'"&X17&"','"&Y17&"','"&U17&"'))" -> a = Client().post('/recipes/varai-khichdi/detail/', {'recipe' : '1', 'ingredient' : '1', 'name' : 'Adrak paste', 'mass_unit' : '2', 'mass_quantity' : '0', 'volume_unit' : '1', 'volume_quantity' : '0.208', 'pieces_unit' : '3', 'pieces_quantity' : '0', 'cooking_notes' : ''}).status_code; print('%s :: %s :: %s :: %s :: %s' %(a,17,'Adrak paste','adrak','Varai Khichdi'))
G18: 18 | H18: Kashmiri Mirchi Pwd | I18: Varai Khichdi | J18: Kashmiri Mirchi Powder | M18: 0.20833333 | N18: cup | R18: =VLOOKUP(J18,ingredient!$N$4:$O$553,2,0) -> kashmiri chilly powder | U18: =I18 -> Varai Khichdi | V18: =VLOOKUP(U18,recipe_ingred_list!$A$2:$B$300,2,0) -> 1 | W18: ="/recipes/"&VLOOKUP(U18,recipe_ingred_list!$A$2:$C$300,3,0)&"/detail/" -> /recipes/varai-khichdi/detail/ | X18: =J18 -> Kashmiri Mirchi Powder | Y18: =R18 -> kashmiri chilly powder | Z18: =VLOOKUP(Y18,recipe_ingred_list!$D$2:$E$500,2,0) -> 117 | AA18: =K18 -> 0 | AB18: =L18 -> 0 | AC18: =VLOOKUP(AB18,recipe_ingred_list!$K$2:$M$7,3,0) -> 2 | AD18: =M18 -> 0.20833333 | AE18: =N18 -> cup | AF18: =VLOOKUP(AE18,recipe_ingred_list!$K$16:$M$25,3,0) -> 5 | AG18: =O18 -> 0 | AH18: =P18 -> 0 | AI18: =VLOOKUP(AH18,recipe_ingred_list!$K$29:$M$34,3,0) -> 3 | AJ18: =IF(Q18="","",Q18) | AK18: =AK17+1 -> 18 | AL18: =Y18 -> kashmiri chilly powder | AM18: ="a = Client().post('"&W18&"', {'recipe' : '"&V18&"', 'ingredient' : '"&Z18&"', 'name' : '"&X18&"', 'mass_unit' : '"&AC18&"', 'mass_quantity' : '"&ROUND(AA18,3)&"', 'volume_unit' : '"&AF18&"', 'volume_quantity' : '"&ROUND(AD18,3)&"', 'pieces_unit' : '"&AI18&"', 'pieces_quantity' : '"&ROUND(AG18,3)&"', 'cooking_notes' : '"&AJ18&"'}).status_code; print('%s :: %s :: %s :: %s :: %s' %(a,"&G18&",'"&X18&"','"&Y18&"','"&U18&"'))" -> a = Client().post('/recipes/varai-khichdi/detail/', {'recipe' : '1', 'ingredient' : '117', 'name' : 'Kashmiri Mirchi Powder', 'mass_unit' : '2', 'mass_quantity' : '0', 'volume_unit' : '5', 'volume_quantity' : '0.208', 'pieces_unit' : '3', 'pieces_quantity' : '0', 'cooking_notes' : ''}).status_code; print('%s :: %s :: %s :: %s :: %s' %(a,18,'Kashmiri Mirchi Powder','kashmiri chilly powder','Varai Khichdi'))
G19: 19 | H19: Tomato | I19: Varai Khichdi | J19: Tomato | K19: 3 | L19: kg | R19: =VLOOKUP(J19,ingredient!$N$4:$O$553,2,0) -> tomato | U19: =I19 -> Varai Khichdi | V19: =VLOOKUP(U19,recipe_ingred_list!$A$2:$B$300,2,0) -> 1 | W19: ="/recipes/"&VLOOKUP(U19,recipe_ingred_list!$A$2:$C$300,3,0)&"/detail/" -> /recipes/varai-khichdi/detail/ | X19: =J19 -> Tomato | Y19: =R19 -> tomato | Z19: =VLOOKUP(Y19,recipe_ingred_list!$D$2:$E$500,2,0) -> 195 | AA19: =K19 -> 3 | AB19: =L19 -> kg | AC19: =VLOOKUP(AB19,recipe_ingred_list!$K$2:$M$7,3,0) -> 2 | AD19: =M19 -> 0 | AE19: =N19 -> 0 | AF19: =VLOOKUP(AE19,recipe_ingred_list!$K$16:$M$25,3,0) -> 1 | AG19: =O19 -> 0 | AH19: =P19 -> 0 | AI19: =VLOOKUP(AH19,recipe_ingred_list!$K$29:$M$34,3,0) -> 3 | AJ19: =IF(Q19="","",Q19) | AK19: =AK18+1 -> 19 | AL19: =Y19 -> tomato | AM19: ="a = Client().post('"&W19&"', {'recipe' : '"&V19&"', 'ingredient' : '"&Z19&"', 'name' : '"&X19&"', 'mass_unit' : '"&AC19&"', 'mass_quantity' : '"&ROUND(AA19,3)&"', 'volume_unit' : '"&AF19&"', 'volume_quantity' : '"&ROUND(AD19,3)&"', 'pieces_unit' : '"&AI19&"', 'pieces_quantity' : '"&ROUND(AG19,3)&"', 'cooking_notes' : '"&AJ19&"'}).status_code; print('%s :: %s :: %s :: %s :: %s' %(a,"&G19&",'"&X19&"','"&Y19&"','"&U19&"'))" -> a = Client().post('/recipes/varai-khichdi/detail/', {'recipe' : '1', 'ingredient' : '195', 'name' : 'Tomato', 'mass_unit' : '2', 'mass_quantity' : '3', 'volume_unit' : '1', 'volume_quantity' : '0', 'pieces_unit' : '3', 'pieces_quantity' : '0', 'cooking_notes' : ''}).status_code; print('%s :: %s :: %s :: %s :: %s' %(a,19,'Tomato','tomato','Varai Khichdi'))
G20: 20 | H20: Ghee | I20: Varai Khichdi | J20: Ghee | M20: 0.5 | N20: ltr | R20: =VLOOKUP(J20,ingredient!$N$4:$O$553,2,0) -> ghee | U20: =I20 -> Varai Khichdi | V20: =VLOOKUP(U20,recipe_ingred_list!$A$2:$B$300,2,0) -> 1 | W20: ="/recipes/"&VLOOKUP(U20,recipe_ingred_list!$A$2:$C$300,3,0)&"/detail/" -> /recipes/varai-khichdi/detail/ | X20: =J20 -> Ghee | Y20: =R20 -> ghee | Z20: =VLOOKUP(Y20,recipe_ingred_list!$D$2:$E$500,2,0) -> 81 | AA20: =K20 -> 0 | AB20: =L20 -> 0 | AC20: =VLOOKUP(AB20,recipe_ingred_list!$K$2:$M$7,3,0) -> 2 | AD20: =M20 -> 0.5 | AE20: =N20 -> ltr | AF20: =VLOOKUP(AE20,recipe_ingred_list!$K$16:$M$25,3,0) -> 1 | AG20: =O20 -> 0 | AH20: =P20 -> 0 | AI20: =VLOOKUP(AH20,recipe_ingred_list!$K$29:$M$34,3,0) -> 3 | AJ20: =IF(Q20="","",Q20) | AK20: =AK19+1 -> 20 | AL20: =Y20 -> ghee | AM20: ="a = Client().post('"&W20&"', {'recipe' : '"&V20&"', 'ingredient' : '"&Z20&"', 'name' : '"&X20&"', 'mass_unit' : '"&AC20&"', 'mass_quantity' : '"&ROUND(AA20,3)&"', 'volume_unit' : '"&AF20&"', 'volume_quantity' : '"&ROUND(AD20,3)&"', 'pieces_unit' : '"&AI20&"', 'pieces_quantity' : '"&ROUND(AG20,3)&"', 'cooking_notes' : '"&AJ20&"'}).status_code; print('%s :: %s :: %s :: %s :: %s' %(a,"&G20&",'"&X20&"','"&Y20&"','"&U20&"'))" -> a = Client().post('/recipes/varai-khichdi/detail/', {'recipe' : '1', 'ingredient' : '81', 'name' : 'Ghee', 'mass_unit' : '2', 'mass_quantity' : '0', 'volume_unit' : '1', 'volume_quantity' : '0.5', 'pieces_unit' : '3', 'pieces_quantity' : '0', 'cooking_notes' : ''}).status_code; print('%s :: %s :: %s :: %s :: %s' %(a,20,'Ghee','ghee','Varai Khichdi'))
G21: 21 | H21: Dhania patta | I21: Varai Khichdi | J21: Dhania patta | M21: 0.1 | N21: bkt | R21: =VLOOKUP(J21,ingredient!$N$4:$O$553,2,0) -> dhaniya patta | U21: =I21 -> Varai Khichdi | V21: =VLOOKUP(U21,recipe_ingred_list!$A$2:$B$300,2,0) -> 1 | W21: ="/recipes/"&VLOOKUP(U21,recipe_ingred_list!$A$2:$C$300,3,0)&"/detail/" -> /recipes/varai-khichdi/detail/ | X21: =J21 -> Dhania patta | Y21: =R21 -> dhaniya patta | Z21: =VLOOKUP(Y21,recipe_ingred_list!$D$2:$E$500,2,0) -> 66 | AA21: =K21 -> 0 | AB21: =L21 -> 0 | AC21: =VLOOKUP(AB21,recipe_ingred_list!$K$2:$M$7,3,0) -> 2 | AD21: =M21 -> 0.1 | AE21: =N21 -> bkt | AF21: =VLOOKUP(AE21,recipe_ingred_list!$K$16:$M$25,3,0) -> 6 | AG21: =O21 -> 0 | AH21: =P21 -> 0 | AI21: =VLOOKUP(AH21,recipe_ingred_list!$K$29:$M$34,3,0) -> 3 | AJ21: =IF(Q21="","",Q21) | AK21: =AK20+1 -> 21 | AL21: =Y21 -> dhaniya patta | AM21: ="a = Client().post('"&W21&"', {'recipe' : '"&V21&"', 'ingredient' : '"&Z21&"', 'name' : '"&X21&"', 'mass_unit' : '"&AC21&"', 'mass_quantity' : '"&ROUND(AA21,3)&"', 'volume_unit' : '"&AF21&"', 'volume_quantity' : '"&ROUND(AD21,3)&"', 'pieces_unit' : '"&AI21&"', 'pieces_quantity' : '"&ROUND(AG21,3)&"', 'cooking_notes' : '"&AJ21&"'}).status_code; print('%s :: %s :: %s :: %s :: %s' %(a,"&G21&",'"&X21&"','"&Y21&"','"&U21&"'))" -> a = Client().post('/recipes/varai-khichdi/detail/', {'recipe' : '1', 'ingredient' : '66', 'name' : 'Dhania patta', 'mass_unit' : '2', 'mass_quantity' : '0', 'volume_unit' : '6', 'volume_quantity' : '0.1', 'pieces_unit' : '3', 'pieces_quantity' : '0', 'cooking_notes' : ''}).status_code; print('%s :: %s :: %s :: %s :: %s' %(a,21,'Dhania patta','dhaniya patta','Varai Khichdi'))
G22: 22 | H22: Jeera pwd | I22: Varai Khichdi | J22: Jeera pwd | M22: 0.083333333 | N22: ltr | R22: =VLOOKUP(J22,ingredient!$N$4:$O$553,2,0) -> jeera powder | U22: =I22 -> Varai Khichdi | V22: =VLOOKUP(U22,recipe_ingred_list!$A$2:$B$300,2,0) -> 1 | W22: ="/recipes/"&VLOOKUP(U22,recipe_ingred_list!$A$2:$C$300,3,0)&"/detail/" -> /recipes/varai-khichdi/detail/ | X22: =J22 -> Jeera pwd | Y22: =R22 -> jeera powder | Z22: =VLOOKUP(Y22,recipe_ingred_list!$D$2:$E$500,2,0) -> 103 | AA22: =K22 -> 0 | AB22: =L22 -> 0 | AC22: =VLOOKUP(AB22,recipe_ingred_list!$K$2:$M$7,3,0) -> 2 | AD22: =M22 -> 0.083333333 | AE22: =N22 -> ltr | AF22: =VLOOKUP(AE22,recipe_ingred_list!$K$16:$M$25,3,0) -> 1 | AG22: =O22 -> 0 | AH22: =P22 -> 0 | AI22: =VLOOKUP(AH22,recipe_ingred_list!$K$29:$M$34,3,0) -> 3 | AJ22: =IF(Q22="","",Q22) | AK22: =AK21+1 -> 22 | AL22: =Y22 -> jeera powder | AM22: ="a = Client().post('"&W22&"', {'recipe' : '"&V22&"', 'ingredient' : '"&Z22&"', 'name' : '"&X22&"', 'mass_unit' : '"&AC22&"', 'mass_quantity' : '"&ROUND(AA22,3)&"', 'volume_unit' : '"&AF22&"', 'volume_quantity' : '"&ROUND(AD22,3)&"', 'pieces_unit' : '"&AI22&"', 'pieces_quantity' : '"&ROUND(AG22,3)&"', 'cooking_notes' : '"&AJ22&"'}).status_code; print('%s :: %s :: %s :: %s :: %s' %(a,"&G22&",'"&X22&"','"&Y22&"','"&U22&"'))" -> a = Client().post('/recipes/varai-khichdi/detail/', {'recipe' : '1', 'ingredient' : '103', 'name' : 'Jeera pwd', 'mass_unit' : '2', 'mass_quantity' : '0', 'volume_unit' : '1', 'volume_quantity' : '0.083', 'pieces_unit' : '3', 'pieces_quantity' : '0', 'cooking_notes' : ''}).status_code; print('%s :: %s :: %s :: %s :: %s' %(a,22,'Jeera pwd','jeera powder','Varai Khichdi'))
G23: 23 | R23: =VLOOKUP(J23,ingredient!$N$4:$O$553,2,0) -> #N/A | U23: =I23 -> 0 | V23: =VLOOKUP(U23,recipe_ingred_list!$A$2:$B$300,2,0) -> #N/A | W23: ="/recipes/"&VLOOKUP(U23,recipe_ingred_list!$A$2:$C$300,3,0)&"/detail/" -> #N/A | X23: =J23 -> 0 | Y23: =R23 -> #N/A | Z23: =VLOOKUP(Y23,recipe_ingred_list!$D$2:$E$500,2,0) -> #N/A | AA23: =K23 -> 0 | AB23: =L23 -> 0 | AC23: =VLOOKUP(AB23,recipe_ingred_list!$K$2:$M$7,3,0) -> 2 | AD23: =M23 -> 0 | AE23: =N23 -> 0 | AF23: =VLOOKUP(AE23,recipe_ingred_list!$K$16:$M$25,3,0) -> 1 | AG23: =O23 -> 0 | AH23: =P23 -> 0 | AI23: =VLOOKUP(AH23,recipe_ingred_list!$K$29:$M$34,3,0) -> 3 | AJ23: =IF(Q23="","",Q23) | AK23: =AK22+1 -> 23 | AL23: =Y23 -> #N/A | AM23: ="a = Client().post('"&W23&"', {'recipe' : '"&V23&"', 'ingredient' : '"&Z23&"', 'name' : '"&X23&"', 'mass_unit' : '"&AC23&"', 'mass_quantity' : '"&ROUND(AA23,3)&"', 'volume_unit' : '"&AF23&"', 'volume_quantity' : '"&ROUND(AD23,3)&"', 'pieces_unit' : '"&AI23&"', 'pieces_quantity' : '"&ROUND(AG23,3)&"', 'cooking_notes' : '"&AJ23&"'}).status_code; print('%s :: %s :: %s :: %s :: %s' %(a,"&G23&",'"&X23&"','"&Y23&"','"&U23&"'))" -> #N/A
G24: 24 | H24: Checking | I24: recipe | J24: Name | K24: mass_quantity | L24: mass_unit | M24: volume_quantity | N24: volume_unit | O24: pieces_quantity | P24: pieces_unit | Q24: Cooking instructions | R24: =VLOOKUP(J24,ingredient!$N$4:$O$553,2,0) -> #N/A | U24: =I24 -> recipe | V24: =VLOOKUP(U24,recipe_ingred_list!$A$2:$B$300,2,0) -> #N/A | W24: ="/recipes/"&VLOOKUP(U24,recipe_ingred_list!$A$2:$C$300,3,0)&"/detail/" -> #N/A | X24: =J24 -> Name | Y24: =R24 -> #N/A | Z24: =VLOOKUP(Y24,recipe_ingred_list!$D$2:$E$500,2,0) -> #N/A | AA24: =K24 -> mass_quantity | AB24: =L24 -> mass_unit | AC24: =VLOOKUP(AB24,recipe_ingred_list!$K$2:$M$7,3,0) -> #N/A | AD24: =M24 -> volume_quantity | AE24: =N24 -> volume_unit | AF24: =VLOOKUP(AE24,recipe_ingred_list!$K$16:$M$25,3,0) -> #N/A | AG24: =O24 -> pieces_quantity | AH24: =P24 -> pieces_unit | AI24: =VLOOKUP(AH24,recipe_ingred_list!$K$29:$M$34,3,0) -> #N/A | AJ24: =IF(Q24="","",Q24) -> Cooking instructions | AK24: =AK23+1 -> 24 | AL24: =Y24 -> #N/A | AM24: ="a = Client().post('"&W24&"', {'recipe' : '"&V24&"', 'ingredient' : '"&Z24&"', 'name' : '"&X24&"', 'mass_unit' : '"&AC24&"', 'mass_quantity' : '"&ROUND(AA24,3)&"', 'volume_unit' : '"&AF24&"', 'volume_quantity' : '"&ROUND(AD24,3)&"', 'pieces_unit' : '"&AI24&"', 'pieces_quantity' : '"&ROUND(AG24,3)&"', 'cooking_notes' : '"&AJ24&"'}).status_code; print('%s :: %s :: %s :: %s :: %s' %(a,"&G24&",'"&X24&"','"&Y24&"','"&U24&"'))" -> #N/A
G25: 25 | H25: Salli | I25: Potato Salli | J25: Salli | K25: 4 | L25: kg | R25: =VLOOKUP(J25,ingredient!$N$4:$O$553,2,0) -> salli | U25: =I25 -> Potato Salli | V25: =VLOOKUP(U25,recipe_ingred_list!$A$2:$B$300,2,0) -> 94 | W25: ="/recipes/"&VLOOKUP(U25,recipe_ingred_list!$A$2:$C$300,3,0)&"/detail/" -> /recipes/potato-salli/detail/ | X25: =J25 -> Salli | Y25: =R25 -> salli | Z25: =VLOOKUP(Y25,recipe_ingred_list!$D$2:$E$500,2,0) -> 215 | AA25: =K25 -> 4 | AB25: =L25 -> kg | AC25: =VLOOKUP(AB25,recipe_ingred_list!$K$2:$M$7,3,0) -> 2 | AD25: =M25 -> 0 | AE25: =N25 -> 0 | AF25: =VLOOKUP(AE25,recipe_ingred_list!$K$16:$M$25,3,0) -> 1 | AG25: =O25 -> 0 | AH25: =P25 -> 0 | AI25: =VLOOKUP(AH25,recipe_ingred_list!$K$29:$M$34,3,0) -> 3 | AJ25: =IF(Q25="","",Q25) | AK25: =AK24+1 -> 25 | AL25: =Y25 -> salli | AM25: ="a = Client().post('"&W25&"', {'recipe' : '"&V25&"', 'ingredient' : '"&Z25&"', 'name' : '"&X25&"', 'mass_unit' : '"&AC25&"', 'mass_quantity' : '"&ROUND(AA25,3)&"', 'volume_unit' : '"&AF25&"', 'volume_quantity' : '"&ROUND(AD25,3)&"', 'pieces_unit' : '"&AI25&"', 'pieces_quantity' : '"&ROUND(AG25,3)&"', 'cooking_notes' : '"&AJ25&"'}).status_code; print('%s :: %s :: %s :: %s :: %s' %(a,"&G25&",'"&X25&"','"&Y25&"','"&U25&"'))" -> a = Client().post('/recipes/potato-salli/detail/', {'recipe' : '94', 'ingredient' : '215', 'name' : 'Salli', 'mass_unit' : '2', 'mass_quantity' : '4', 'volume_unit' : '1', 'volume_quantity' : '0', 'pieces_unit' : '3', 'pieces_quantity' : '0', 'cooking_notes' : ''}).status_code; print('%s :: %s :: %s :: %s :: %s' %(a,25,'Salli','salli','Potato Salli'))
G26: 26 | H26: Black Pepper Pwd | I26: Potato Salli | J26: Black Pepper Pwd | M26: 0.5 | N26: cup | R26: =VLOOKUP(J26,ingredient!$N$4:$O$553,2,0) -> black pepper | U26: =I26 -> Potato Salli | V26: =VLOOKUP(U26,recipe_ingred_list!$A$2:$B$300,2,0) -> 94 | W26: ="/recipes/"&VLOOKUP(U26,recipe_ingred_list!$A$2:$C$300,3,0)&"/detail/" -> /recipes/potato-salli/detail/ | X26: =J26 -> Black Pepper Pwd | Y26: =R26 -> black pepper | Z26: =VLOOKUP(Y26,recipe_ingred_list!$D$2:$E$500,2,0) -> 31 | AA26: =K26 -> 0 | AB26: =L26 -> 0 | AC26: =VLOOKUP(AB26,recipe_ingred_list!$K$2:$M$7,3,0) -> 2 | AD26: =M26 -> 0.5 | AE26: =N26 -> cup | AF26: =VLOOKUP(AE26,recipe_ingred_list!$K$16:$M$25,3,0) -> 5 | AG26: =O26 -> 0 | AH26: =P26 -> 0 | AI26: =VLOOKUP(AH26,recipe_ingred_list!$K$29:$M$34,3,0) -> 3 | AJ26: =IF(Q26="","",Q26) | AK26: =AK25+1 -> 26 | AL26: =Y26 -> black pepper | AM26: ="a = Client().post('"&W26&"', {'recipe' : '"&V26&"', 'ingredient' : '"&Z26&"', 'name' : '"&X26&"', 'mass_unit' : '"&AC26&"', 'mass_quantity' : '"&ROUND(AA26,3)&"', 'volume_unit' : '"&AF26&"', 'volume_quantity' : '"&ROUND(AD26,3)&"', 'pieces_unit' : '"&AI26&"', 'pieces_quantity' : '"&ROUND(AG26,3)&"', 'cooking_notes' : '"&AJ26&"'}).status_code; print('%s :: %s :: %s :: %s :: %s' %(a,"&G26&",'"&X26&"','"&Y26&"','"&U26&"'))" -> a = Client().post('/recipes/potato-salli/detail/', {'recipe' : '94', 'ingredient' : '31', 'name' : 'Black Pepper Pwd', 'mass_unit' : '2', 'mass_quantity' : '0', 'volume_unit' : '5', 'volume_quantity' : '0.5', 'pieces_unit' : '3', 'pieces_quantity' : '0', 'cooking_notes' : ''}).status_code; print('%s :: %s :: %s :: %s :: %s' %(a,26,'Black Pepper Pwd','black pepper','Potato Salli'))
G27: 27 | H27: Black Salt | I27: Potato Salli | J27: Black Salt | M27: 0.5 | N27: cup | R27: =VLOOKUP(J27,ingredient!$N$4:$O$553,2,0) -> black salt | U27: =I27 -> Potato Salli | V27: =VLOOKUP(U27,recipe_ingred_list!$A$2:$B$300,2,0) -> 94 | W27: ="/recipes/"&VLOOKUP(U27,recipe_ingred_list!$A$2:$C$300,3,0)&"/detail/" -> /recipes/potato-salli/detail/ | X27: =J27 -> Black Salt | Y27: =R27 -> black salt | Z27: =VLOOKUP(Y27,recipe_ingred_list!$D$2:$E$500,2,0) -> 32 | AA27: =K27 -> 0 | AB27: =L27 -> 0 | AC27: =VLOOKUP(AB27,recipe_ingred_list!$K$2:$M$7,3,0) -> 2 | AD27: =M27 -> 0.5 | AE27: =N27 -> cup | AF27: =VLOOKUP(AE27,recipe_ingred_list!$K$16:$M$25,3,0) -> 5 | AG27: =O27 -> 0 | AH27: =P27 -> 0 | AI27: =VLOOKUP(AH27,recipe_ingred_list!$K$29:$M$34,3,0) -> 3 | AJ27: =IF(Q27="","",Q27) | AK27: =AK26+1 -> 27 | AL27: =Y27 -> black salt | AM27: ="a = Client().post('"&W27&"', {'recipe' : '"&V27&"', 'ingredient' : '"&Z27&"', 'name' : '"&X27&"', 'mass_unit' : '"&AC27&"', 'mass_quantity' : '"&ROUND(AA27,3)&"', 'volume_unit' : '"&AF27&"', 'volume_quantity' : '"&ROUND(AD27,3)&"', 'pieces_unit' : '"&AI27&"', 'pieces_quantity' : '"&ROUND(AG27,3)&"', 'cooking_notes' : '"&AJ27&"'}).status_code; print('%s :: %s :: %s :: %s :: %s' %(a,"&G27&",'"&X27&"','"&Y27&"','"&U27&"'))" -> a = Client().post('/recipes/potato-salli/detail/', {'recipe' : '94', 'ingredient' : '32', 'name' : 'Black Salt', 'mass_unit' : '2', 'mass_quantity' : '0', 'volume_unit' : '5', 'volume_quantity' : '0.5', 'pieces_unit' : '3', 'pieces_quantity' : '0', 'cooking_notes' : ''}).status_code; print('%s :: %s :: %s :: %s :: %s' %(a,27,'Black Salt','black salt','Potato Salli'))
G28: 28 | H28: Salt | I28: Potato Salli | J28: Salt | M28: 0.5 | N28: cup | R28: =VLOOKUP(J28,ingredient!$N$4:$O$553,2,0) -> salt | U28: =I28 -> Potato Salli | V28: =VLOOKUP(U28,recipe_ingred_list!$A$2:$B$300,2,0) -> 94 | W28: ="/recipes/"&VLOOKUP(U28,recipe_ingred_list!$A$2:$C$300,3,0)&"/detail/" -> /recipes/potato-salli/detail/ | X28: =J28 -> Salt | Y28: =R28 -> salt | Z28: =VLOOKUP(Y28,recipe_ingred_list!$D$2:$E$500,2,0) -> 177 | AA28: =K28 -> 0 | AB28: =L28 -> 0 | AC28: =VLOOKUP(AB28,recipe_ingred_list!$K$2:$M$7,3,0) -> 2 | AD28: =M28 -> 0.5 | AE28: =N28 -> cup | AF28: =VLOOKUP(AE28,recipe_ingred_list!$K$16:$M$25,3,0) -> 5 | AG28: =O28 -> 0 | AH28: =P28 -> 0 | AI28: =VLOOKUP(AH28,recipe_ingred_list!$K$29:$M$34,3,0) -> 3 | AJ28: =IF(Q28="","",Q28) | AK28: =AK27+1 -> 28 | AL28: =Y28 -> salt | AM28: ="a = Client().post('"&W28&"', {'recipe' : '"&V28&"', 'ingredient' : '"&Z28&"', 'name' : '"&X28&"', 'mass_unit' : '"&AC28&"', 'mass_quantity' : '"&ROUND(AA28,3)&"', 'volume_unit' : '"&AF28&"', 'volume_quantity' : '"&ROUND(AD28,3)&"', 'pieces_unit' : '"&AI28&"', 'pieces_quantity' : '"&ROUND(AG28,3)&"', 'cooking_notes' : '"&AJ28&"'}).status_code; print('%s :: %s :: %s :: %s :: %s' %(a,"&G28&",'"&X28&"','"&Y28&"','"&U28&"'))" -> a = Client().post('/recipes/potato-salli/detail/', {'recipe' : '94', 'ingredient' : '177', 'name' : 'Salt', 'mass_unit' : '2', 'mass_quantity' : '0', 'volume_unit' : '5', 'volume_quantity' : '0.5', 'pieces_unit' : '3', 'pieces_quantity' : '0', 'cooking_notes' : ''}).status_code; print('%s :: %s :: %s :: %s :: %s' %(a,28,'Salt','salt','Potato Salli'))
G29: 29 | H29: Oil for frying | I29: Potato Salli | J29: Oil for frying | M29: 0 | N29: ltr | R29: =VLOOKUP(J29,ingredient!$N$4:$O$553,2,0) -> gound nut oil | U29: =I29 -> Potato Salli | V29: =VLOOKUP(U29,recipe_ingred_list!$A$2:$B$300,2,0) -> 94 | W29: ="/recipes/"&VLOOKUP(U29,recipe_ingred_list!$A$2:$C$300,3,0)&"/detail/" -> /recipes/potato-salli/detail/ | X29: =J29 -> Oil for frying | Y29: =R29 -> gound nut oil | Z29: =VLOOKUP(Y29,recipe_ingred_list!$D$2:$E$500,2,0) -> 83 | AA29: =K29 -> 0 | AB29: =L29 -> 0 | AC29: =VLOOKUP(AB29,recipe_ingred_list!$K$2:$M$7,3,0) -> 2 | AD29: =M29 -> 0 | AE29: =N29 -> ltr | AF29: =VLOOKUP(AE29,recipe_ingred_list!$K$16:$M$25,3,0) -> 1 | AG29: =O29 -> 0 | AH29: =P29 -> 0 | AI29: =VLOOKUP(AH29,recipe_ingred_list!$K$29:$M$34,3,0) -> 3 | AJ29: =IF(Q29="","",Q29) | AK29: =AK28+1 -> 29 | AL29: =Y29 -> gound nut oil | AM29: ="a = Client().post('"&W29&"', {'recipe' : '"&V29&"', 'ingredient' : '"&Z29&"', 'name' : '"&X29&"', 'mass_unit' : '"&AC29&"', 'mass_quantity' : '"&ROUND(AA29,3)&"', 'volume_unit' : '"&AF29&"', 'volume_quantity' : '"&ROUND(AD29,3)&"', 'pieces_unit' : '"&AI29&"', 'pieces_quantity' : '"&ROUND(AG29,3)&"', 'cooking_notes' : '"&AJ29&"'}).status_code; print('%s :: %s :: %s :: %s :: %s' %(a,"&G29&",'"&X29&"','"&Y29&"','"&U29&"'))" -> a = Client().post('/recipes/potato-salli/detail/', {'recipe' : '94', 'ingredient' : '83', 'name' : 'Oil for frying ', 'mass_unit' : '2', 'mass_quantity' : '0', 'volume_unit' : '1', 'volume_quantity' : '0', 'pieces_unit' : '3', 'pieces_quantity' : '0', 'cooking_notes' : ''}).status_code; print('%s :: %s :: %s :: %s :: %s' %(a,29,'Oil for frying ','gound nut oil','Potato Salli'))
G30: 30 | R30: =VLOOKUP(J30,ingredient!$N$4:$O$553,2,0) -> #N/A | U30: =I30 -> 0 | V30: =VLOOKUP(U30,recipe_ingred_list!$A$2:$B$300,2,0) -> #N/A | W30: ="/recipes/"&VLOOKUP(U30,recipe_ingred_list!$A$2:$C$300,3,0)&"/detail/" -> #N/A | X30: =J30 -> 0 | Y30: =R30 -> #N/A | Z30: =VLOOKUP(Y30,recipe_ingred_list!$D$2:$E$500,2,0) -> #N/A | AA30: =K30 -> 0 | AB30: =L30 -> 0 | AC30: =VLOOKUP(AB30,recipe_ingred_list!$K$2:$M$7,3,0) -> 2 | AD30: =M30 -> 0 | AE30: =N30 -> 0 | AF30: =VLOOKUP(AE30,recipe_ingred_list!$K$16:$M$25,3,0) -> 1 | AG30: =O30 -> 0 | AH30: =P30 -> 0 | AI30: =VLOOKUP(AH30,recipe_ingred_list!$K$29:$M$34,3,0) -> 3 | AJ30: =IF(Q30="","",Q30) | AK30: =AK29+1 -> 30 | AL30: =Y30 -> #N/A | AM30: ="a = Client().post('"&W30&"', {'recipe' : '"&V30&"', 'ingredient' : '"&Z30&"', 'name' : '"&X30&"', 'mass_unit' : '"&AC30&"', 'mass_quantity' : '"&ROUND(AA30,3)&"', 'volume_unit' : '"&AF30&"', 'volume_quantity' : '"&ROUND(AD30,3)&"', 'pieces_unit' : '"&AI30&"', 'pieces_quantity' : '"&ROUND(AG30,3)&"', 'cooking_notes' : '"&AJ30&"'}).status_code; print('%s :: %s :: %s :: %s :: %s' %(a,"&G30&",'"&X30&"','"&Y30&"','"&U30&"'))" -> #N/A
G31: 31 | H31: Checking | I31: recipe | J31: Name | K31: mass_quantity | L31: mass_unit | M31: volume_quantity | N31: volume_unit | O31: pieces_quantity | P31: pieces_unit | Q31: Cooking instructions | R31: =VLOOKUP(J31,ingredient!$N$4:$O$553,2,0) -> #N/A | U31: =I31 -> recipe | V31: =VLOOKUP(U31,recipe_ingred_list!$A$2:$B$300,2,0) -> #N/A | W31: ="/recipes/"&VLOOKUP(U31,recipe_ingred_list!$A$2:$C$300,3,0)&"/detail/" -> #N/A | X31: =J31 -> Name | Y31: =R31 -> #N/A | Z31: =VLOOKUP(Y31,recipe_ingred_list!$D$2:$E$500,2,0) -> #N/A | AA31: =K31 -> mass_quantity | AB31: =L31 -> mass_unit | AC31: =VLOOKUP(AB31,recipe_ingred_list!$K$2:$M$7,3,0) -> #N/A | AD31: =M31 -> volume_quantity | AE31: =N31 -> volume_unit | AF31: =VLOOKUP(AE31,recipe_ingred_list!$K$16:$M$25,3,0) -> #N/A | AG31: =O31 -> pieces_quantity | AH31: =P31 -> pieces_unit | AI31: =VLOOKUP(AH31,recipe_ingred_list!$K$29:$M$34,3,0) -> #N/A | AJ31: =IF(Q31="","",Q31) -> Cooking instructions | AK31: =AK30+1 -> 31 | AL31: =Y31 -> #N/A | AM31: ="a = Client().post('"&W31&"', {'recipe' : '"&V31&"', 'ingredient' : '"&Z31&"', 'name' : '"&X31&"', 'mass_unit' : '"&AC31&"', 'mass_quantity' : '"&ROUND(AA31,3)&"', 'volume_unit' : '"&AF31&"', 'volume_quantity' : '"&ROUND(AD31,3)&"', 'pieces_unit' : '"&AI31&"', 'pieces_quantity' : '"&ROUND(AG31,3)&"', 'cooking_notes' : '"&AJ31&"'}).status_code; print('%s :: %s :: %s :: %s :: %s' %(a,"&G31&",'"&X31&"','"&Y31&"','"&U31&"'))" -> #N/A
G32: 32 | H32: Varai rice | I32: Varai Pulav2 | J32: Varai rice | K32: 30 | L32: kg | R32: =VLOOKUP(J32,ingredient!$N$4:$O$553,2,0) -> varai | U32: =I32 -> Varai Pulav2 | V32: =VLOOKUP(U32,recipe_ingred_list!$A$2:$B$300,2,0) -> 96 | W32: ="/recipes/"&VLOOKUP(U32,recipe_ingred_list!$A$2:$C$300,3,0)&"/detail/" -> /recipes/varai-pulav2/detail/ | X32: =J32 -> Varai rice | Y32: =R32 -> varai | Z32: =VLOOKUP(Y32,recipe_ingred_list!$D$2:$E$500,2,0) -> 201 | AA32: =K32 -> 30 | AB32: =L32 -> kg | AC32: =VLOOKUP(AB32,recipe_ingred_list!$K$2:$M$7,3,0) -> 2 | AD32: =M32 -> 0 | AE32: =N32 -> 0 | AF32: =VLOOKUP(AE32,recipe_ingred_list!$K$16:$M$25,3,0) -> 1 | AG32: =O32 -> 0 | AH32: =P32 -> 0 | AI32: =VLOOKUP(AH32,recipe_ingred_list!$K$29:$M$34,3,0) -> 3 | AJ32: =IF(Q32="","",Q32) | AK32: =AK31+1 -> 32 | AL32: =Y32 -> varai | AM32: ="a = Client().post('"&W32&"', {'recipe' : '"&V32&"', 'ingredient' : '"&Z32&"', 'name' : '"&X32&"', 'mass_unit' : '"&AC32&"', 'mass_quantity' : '"&ROUND(AA32,3)&"', 'volume_unit' : '"&AF32&"', 'volume_quantity' : '"&ROUND(AD32,3)&"', 'pieces_unit' : '"&AI32&"', 'pieces_quantity' : '"&ROUND(AG32,3)&"', 'cooking_notes' : '"&AJ32&"'}).status_code; print('%s :: %s :: %s :: %s :: %s' %(a,"&G32&",'"&X32&"','"&Y32&"','"&U32&"'))" -> a = Client().post('/recipes/varai-pulav2/detail/', {'recipe' : '96', 'ingredient' : '201', 'name' : 'Varai rice', 'mass_unit' : '2', 'mass_quantity' : '30', 'volume_unit' : '1', 'volume_quantity' : '0', 'pieces_unit' : '3', 'pieces_quantity' : '0', 'cooking_notes' : ''}).status_code; print('%s :: %s :: %s :: %s :: %s' %(a,32,'Varai rice','varai','Varai Pulav2'))
G33: 33 | H33: Groundnut Oil | I33: Varai Pulav2 | J33: Groundnut oil for tadka | M33: 10 | N33: ltr | R33: =VLOOKUP(J33,ingredient!$N$4:$O$553,2,0) -> ground nut oil | U33: =I33 -> Varai Pulav2 | V33: =VLOOKUP(U33,recipe_ingred_list!$A$2:$B$300,2,0) -> 96 | W33: ="/recipes/"&VLOOKUP(U33,recipe_ingred_list!$A$2:$C$300,3,0)&"/detail/" -> /recipes/varai-pulav2/detail/ | X33: =J33 -> Groundnut oil for tadka | Y33: =R33 -> ground nut oil | Z33: =VLOOKUP(Y33,recipe_ingred_list!$D$2:$E$500,2,0) -> 89 | AA33: =K33 -> 0 | AB33: =L33 -> 0 | AC33: =VLOOKUP(AB33,recipe_ingred_list!$K$2:$M$7,3,0) -> 2 | AD33: =M33 -> 10 | AE33: =N33 -> ltr | AF33: =VLOOKUP(AE33,recipe_ingred_list!$K$16:$M$25,3,0) -> 1 | AG33: =O33 -> 0 | AH33: =P33 -> 0 | AI33: =VLOOKUP(AH33,recipe_ingred_list!$K$29:$M$34,3,0) -> 3 | AJ33: =IF(Q33="","",Q33) | AK33: =AK32+1 -> 33 | AL33: =Y33 -> ground nut oil | AM33: ="a = Client().post('"&W33&"', {'recipe' : '"&V33&"', 'ingredient' : '"&Z33&"', 'name' : '"&X33&"', 'mass_unit' : '"&AC33&"', 'mass_quantity' : '"&ROUND(AA33,3)&"', 'volume_unit' : '"&AF33&"', 'volume_quantity' : '"&ROUND(AD33,3)&"', 'pieces_unit' : '"&AI33&"', 'pieces_quantity' : '"&ROUND(AG33,3)&"', 'cooking_notes' : '"&AJ33&"'}).status_code; print('%s :: %s :: %s :: %s :: %s' %(a,"&G33&",'"&X33&"','"&Y33&"','"&U33&"'))" -> a = Client().post('/recipes/varai-pulav2/detail/', {'recipe' : '96', 'ingredient' : '89', 'name' : 'Groundnut oil for tadka', 'mass_unit' : '2', 'mass_quantity' : '0', 'volume_unit' : '1', 'volume_quantity' : '10', 'pieces_unit' : '3', 'pieces_quantity' : '0', 'cooking_notes' : ''}).status_code; print('%s :: %s :: %s :: %s :: %s' %(a,33,'Groundnut oil for tadka','ground nut oil','Varai Pulav2'))
G34: 34 | H34: Tejpatta | I34: Varai Pulav2 | J34: Tejpatta | M34: 1 | N34: ltr | R34: =VLOOKUP(J34,ingredient!$N$4:$O$553,2,0) -> tej patta | U34: =I34 -> Varai Pulav2 | V34: =VLOOKUP(U34,recipe_ingred_list!$A$2:$B$300,2,0) -> 96 | W34: ="/recipes/"&VLOOKUP(U34,recipe_ingred_list!$A$2:$C$300,3,0)&"/detail/" -> /recipes/varai-pulav2/detail/ | X34: =J34 -> Tejpatta | Y34: =R34 -> tej patta | Z34: =VLOOKUP(Y34,recipe_ingred_list!$D$2:$E$500,2,0) -> 191 | AA34: =K34 -> 0 | AB34: =L34 -> 0 | AC34: =VLOOKUP(AB34,recipe_ingred_list!$K$2:$M$7,3,0) -> 2 | AD34: =M34 -> 1 | AE34: =N34 -> ltr | AF34: =VLOOKUP(AE34,recipe_ingred_list!$K$16:$M$25,3,0) -> 1 | AG34: =O34 -> 0 | AH34: =P34 -> 0 | AI34: =VLOOKUP(AH34,recipe_ingred_list!$K$29:$M$34,3,0) -> 3 | AJ34: =IF(Q34="","",Q34) | AK34: =AK33+1 -> 34 | AL34: =Y34 -> tej patta | AM34: ="a = Client().post('"&W34&"', {'recipe' : '"&V34&"', 'ingredient' : '"&Z34&"', 'name' : '"&X34&"', 'mass_unit' : '"&AC34&"', 'mass_quantity' : '"&ROUND(AA34,3)&"', 'volume_unit' : '"&AF34&"', 'volume_quantity' : '"&ROUND(AD34,3)&"', 'pieces_unit' : '"&AI34&"', 'pieces_quantity' : '"&ROUND(AG34,3)&"', 'cooking_notes' : '"&AJ34&"'}).status_code; print('%s :: %s :: %s :: %s :: %s' %(a,"&G34&",'"&X34&"','"&Y34&"','"&U34&"'))" -> a = Client().post('/recipes/varai-pulav2/detail/', {'recipe' : '96', 'ingredient' : '191', 'name' : 'Tejpatta', 'mass_unit' : '2', 'mass_quantity' : '0', 'volume_unit' : '1', 'volume_quantity' : '1', 'pieces_unit' : '3', 'pieces_quantity' : '0', 'cooking_notes' : ''}).status_code; print('%s :: %s :: %s :: %s :: %s' %(a,34,'Tejpatta','tej patta','Varai Pulav2'))
G35: 35 | H35: Jeera | I35: Varai Pulav2 | J35: Jeera | M35: 0.75 | N35: ltr | R35: =VLOOKUP(J35,ingredient!$N$4:$O$553,2,0) -> jeera | U35: =I35 -> Varai Pulav2 | V35: =VLOOKUP(U35,recipe_ingred_list!$A$2:$B$300,2,0) -> 96 | W35: ="/recipes/"&VLOOKUP(U35,recipe_ingred_list!$A$2:$C$300,3,0)&"/detail/" -> /recipes/varai-pulav2/detail/ | X35: =J35 -> Jeera | Y35: =R35 -> jeera | Z35: =VLOOKUP(Y35,recipe_ingred_list!$D$2:$E$500,2,0) -> 102 | AA35: =K35 -> 0 | AB35: =L35 -> 0 | AC35: =VLOOKUP(AB35,recipe_ingred_list!$K$2:$M$7,3,0) -> 2 | AD35: =M35 -> 0.75 | AE35: =N35 -> ltr | AF35: =VLOOKUP(AE35,recipe_ingred_list!$K$16:$M$25,3,0) -> 1 | AG35: =O35 -> 0 | AH35: =P35 -> 0 | AI35: =VLOOKUP(AH35,recipe_ingred_list!$K$29:$M$34,3,0) -> 3 | AJ35: =IF(Q35="","",Q35) | AK35: =AK34+1 -> 35 | AL35: =Y35 -> jeera | AM35: ="a = Client().post('"&W35&"', {'recipe' : '"&V35&"', 'ingredient' : '"&Z35&"', 'name' : '"&X35&"', 'mass_unit' : '"&AC35&"', 'mass_quantity' : '"&ROUND(AA35,3)&"', 'volume_unit' : '"&AF35&"', 'volume_quantity' : '"&ROUND(AD35,3)&"', 'pieces_unit' : '"&AI35&"', 'pieces_quantity' : '"&ROUND(AG35,3)&"', 'cooking_notes' : '"&AJ35&"'}).status_code; print('%s :: %s :: %s :: %s :: %s' %(a,"&G35&",'"&X35&"','"&Y35&"','"&U35&"'))" -> a = Client().post('/recipes/varai-pulav2/detail/', {'recipe' : '96', 'ingredient' : '102', 'name' : 'Jeera', 'mass_unit' : '2', 'mass_quantity' : '0', 'volume_unit' : '1', 'volume_quantity' : '0.75', 'pieces_unit' : '3', 'pieces_quantity' : '0', 'cooking_notes' : ''}).status_code; print('%s :: %s :: %s :: %s :: %s' %(a,35,'Jeera','jeera','Varai Pulav2'))
G36: 36 | H36: kadi patta | I36: Varai Pulav2 | J36: kadi patta | M36: 2 | N36: ltr | R36: =VLOOKUP(J36,ingredient!$N$4:$O$553,2,0) -> kadi patta | U36: =I36 -> Varai Pulav2 | V36: =VLOOKUP(U36,recipe_ingred_list!$A$2:$B$300,2,0) -> 96 | W36: ="/recipes/"&VLOOKUP(U36,recipe_ingred_list!$A$2:$C$300,3,0)&"/detail/" -> /recipes/varai-pulav2/detail/ | X36: =J36 -> kadi patta | Y36: =R36 -> kadi patta | Z36: =VLOOKUP(Y36,recipe_ingred_list!$D$2:$E$500,2,0) -> 105 | AA36: =K36 -> 0 | AB36: =L36 -> 0 | AC36: =VLOOKUP(AB36,recipe_ingred_list!$K$2:$M$7,3,0) -> 2 | AD36: =M36 -> 2 | AE36: =N36 -> ltr | AF36: =VLOOKUP(AE36,recipe_ingred_list!$K$16:$M$25,3,0) -> 1 | AG36: =O36 -> 0 | AH36: =P36 -> 0 | AI36: =VLOOKUP(AH36,recipe_ingred_list!$K$29:$M$34,3,0) -> 3 | AJ36: =IF(Q36="","",Q36) | AK36: =AK35+1 -> 36 | AL36: =Y36 -> kadi patta | AM36: ="a = Client().post('"&W36&"', {'recipe' : '"&V36&"', 'ingredient' : '"&Z36&"', 'name' : '"&X36&"', 'mass_unit' : '"&AC36&"', 'mass_quantity' : '"&ROUND(AA36,3)&"', 'volume_unit' : '"&AF36&"', 'volume_quantity' : '"&ROUND(AD36,3)&"', 'pieces_unit' : '"&AI36&"', 'pieces_quantity' : '"&ROUND(AG36,3)&"', 'cooking_notes' : '"&AJ36&"'}).status_code; print('%s :: %s :: %s :: %s :: %s' %(a,"&G36&",'"&X36&"','"&Y36&"','"&U36&"'))" -> a = Client().post('/recipes/varai-pulav2/detail/', {'recipe' : '96', 'ingredient' : '105', 'name' : 'kadi patta', 'mass_unit' : '2', 'mass_quantity' : '0', 'volume_unit' : '1', 'volume_quantity' : '2', 'pieces_unit' : '3', 'pieces_quantity' : '0', 'cooking_notes' : ''}).status_code; print('%s :: %s :: %s :: %s :: %s' %(a,36,'kadi patta','kadi patta','Varai Pulav2'))
G37: 37 | H37: Gajar | I37: Varai Pulav2 | J37: Gajar | K37: 4 | L37: kg | M37: 5 | N37: ltr | R37: =VLOOKUP(J37,ingredient!$N$4:$O$553,2,0) -> gajar | U37: =I37 -> Varai Pulav2 | V37: =VLOOKUP(U37,recipe_ingred_list!$A$2:$B$300,2,0) -> 96 | W37: ="/recipes/"&VLOOKUP(U37,recipe_ingred_list!$A$2:$C$300,3,0)&"/detail/" -> /recipes/varai-pulav2/detail/ | X37: =J37 -> Gajar | Y37: =R37 -> gajar | Z37: =VLOOKUP(Y37,recipe_ingred_list!$D$2:$E$500,2,0) -> 79 | AA37: =K37 -> 4 | AB37: =L37 -> kg | AC37: =VLOOKUP(AB37,recipe_ingred_list!$K$2:$M$7,3,0) -> 2 | AD37: =M37 -> 5 | AE37: =N37 -> ltr | AF37: =VLOOKUP(AE37,recipe_ingred_list!$K$16:$M$25,3,0) -> 1 | AG37: =O37 -> 0 | AH37: =P37 -> 0 | AI37: =VLOOKUP(AH37,recipe_ingred_list!$K$29:$M$34,3,0) -> 3 | AJ37: =IF(Q37="","",Q37) | AK37: =AK36+1 -> 37 | AL37: =Y37 -> gajar | AM37: ="a = Client().post('"&W37&"', {'recipe' : '"&V37&"', 'ingredient' : '"&Z37&"', 'name' : '"&X37&"', 'mass_unit' : '"&AC37&"', 'mass_quantity' : '"&ROUND(AA37,3)&"', 'volume_unit' : '"&AF37&"', 'volume_quantity' : '"&ROUND(AD37,3)&"', 'pieces_unit' : '"&AI37&"', 'pieces_quantity' : '"&ROUND(AG37,3)&"', 'cooking_notes' : '"&AJ37&"'}).status_code; print('%s :: %s :: %s :: %s :: %s' %(a,"&G37&",'"&X37&"','"&Y37&"','"&U37&"'))" -> a = Client().post('/recipes/varai-pulav2/detail/', {'recipe' : '96', 'ingredient' : '79', 'name' : 'Gajar', 'mass_unit' : '2', 'mass_quantity' : '4', 'volume_unit' : '1', 'volume_quantity' : '5', 'pieces_unit' : '3', 'pieces_quantity' : '0', 'cooking_notes' : ''}).status_code; print('%s :: %s :: %s :: %s :: %s' %(a,37,'Gajar','gajar','Varai Pulav2'))
